Workbook

Sheet DASHBOARD
A1: 📊 Simulador e Controle de Investimentos
A2: Corretora: Rico
A4: 💰 Custo Total Investido | B4: 📈 Patrimônio Atual | C4: 🟢 Resultado R$ | D4: 📊 Rentabilidade | E4: 💵 Proventos Recebidos | F4: 🏦 Qtd Ativos em Carteira
A5: =SUM(CARTEIRA!H6:H100) | B5: =SUM(CARTEIRA!K6:K100) | C5: =B5-A5 | D5: =IFERROR(C5/A5, 0) | E5: =SUM(PROVENTOS!G5:G100) | F5: =COUNTIF(CARTEIRA!H6:H100, ">0")
J7: Segmento | K7: Valor Actual
J8: Títulos e Valores Mobiliários | K8: =SUMIF(CARTEIRA!$N$6:$N$100, J8, CARTEIRA!$K$6:$K$100)
J9: Logístico / Galpões | K9: =SUMIF(CARTEIRA!$N$6:$N$100, J9, CARTEIRA!$K$6:$K$100)
J10: Shoppings / Varejo | K10: =SUMIF(CARTEIRA!$N$6:$N$100, J10, CARTEIRA!$K$6:$K$100)
J11: Híbrido | K11: =SUMIF(CARTEIRA!$N$6:$N$100, J11, CARTEIRA!$K$6:$K$100)
J12: FI-Infra | K12: =SUMIF(CARTEIRA!$N$6:$N$100, J12, CARTEIRA!$K$6:$K$100)
J14: Corretora | K14: Valor
J15: Rico | K15: =SUMIF(CARTEIRA!$B$6:$B$100, J15, CARTEIRA!$K$6:$K$100)
J16: XP | K16: =SUMIF(CARTEIRA!$B$6:$B$100, J16, CARTEIRA!$K$6:$K$100)
J17: BTG | K17: =SUMIF(CARTEIRA!$B$6:$B$100, J17, CARTEIRA!$K$6:$K$100)
J18: Outras | K18: =SUM(CARTEIRA!$K$6:$K$100)-SUM(K15:K17)
J20: Mês | K20: Proventos
J21: Janeiro | K21: =SUMIF(PROVENTOS!$B$5:$B$100, J21, PROVENTOS!$G$5:$G$100)
J22: Fevereiro | K22: =SUMIF(PROVENTOS!$B$5:$B$100, J22, PROVENTOS!$G$5:$G$100)
J23: Março | K23: =SUMIF(PROVENTOS!$B$5:$B$100, J23, PROVENTOS!$G$5:$G$100)
J24: Abril | K24: =SUMIF(PROVENTOS!$B$5:$B$100, J24, PROVENTOS!$G$5:$G$100)
J25: Maio | K25: =SUMIF(PROVENTOS!$B$5:$B$100, J25, PROVENTOS!$G$5:$G$100)
J26: Junho | K26: =SUMIF(PROVENTOS!$B$5:$B$100, J26, PROVENTOS!$G$5:$G$100)
J27: Julho | K27: =SUMIF(PROVENTOS!$B$5:$B$100, J27, PROVENTOS!$G$5:$G$100)
J28: Agosto | K28: =SUMIF(PROVENTOS!$B$5:$B$100, J28, PROVENTOS!$G$5:$G$100)
J29: Setembro | K29: =SUMIF(PROVENTOS!$B$5:$B$100, J29, PROVENTOS!$G$5:$G$100)
J30: Outubro | K30: =SUMIF(PROVENTOS!$B$5:$B$100, J30, PROVENTOS!$G$5:$G$100)
J31: Novembro | K31: =SUMIF(PROVENTOS!$B$5:$B$100, J31, PROVENTOS!$G$5:$G$100)
J32: Dezembro | K32: =SUMIF(PROVENTOS!$B$5:$B$100, J32, PROVENTOS!$G$5:$G$100)
J34: Mês | K34: Aportes
J35: Janeiro | K35: =SUMIF(APORTES!$B$5:$B$100, J35, APORTES!$D$5:$D$100)
J36: Fevereiro | K36: =SUMIF(APORTES!$B$5:$B$100, J36, APORTES!$D$5:$D$100)
J37: Março | K37: =SUMIF(APORTES!$B$5:$B$100, J37, APORTES!$D$5:$D$100)
J38: Abril | K38: =SUMIF(APORTES!$B$5:$B$100, J38, APORTES!$D$5:$D$100)
J39: Maio | K39: =SUMIF(APORTES!$B$5:$B$100, J39, APORTES!$D$5:$D$100)
J40: Junho | K40: =SUMIF(APORTES!$B$5:$B$100, J40, APORTES!$D$5:$D$100)
J41: Julho | K41: =SUMIF(APORTES!$B$5:$B$100, J41, APORTES!$D$5:$D$100)
J42: Agosto | K42: =SUMIF(APORTES!$B$5:$B$100, J42, APORTES!$D$5:$D$100)
J43: Setembro | K43: =SUMIF(APORTES!$B$5:$B$100, J43, APORTES!$D$5:$D$100)
J44: Outubro | K44: =SUMIF(APORTES!$B$5:$B$100, J44, APORTES!$D$5:$D$100)
J45: Novembro | K45: =SUMIF(APORTES!$B$5:$B$100, J45, APORTES!$D$5:$D$100)
...

Sheet LISTAS
A1: Corretoras | B1: Tipos | C1: Segmentos
A2: Rico | B2: FII | C2: Títulos e Valores Mobiliários
A3: XP | B3: Ação | C3: Logístico / Galpões
A4: NuInvest | B4: ETF | C4: Shoppings / Varejo
A5: BTG | B5: FI-Infra | C5: Híbrido
A6: Inter | B6: BDR | C6: FI-Infra
A7: Clear | B7: Outros
A8: Outra

Sheet BASE_ATIVOS
A1: 📊 Simulador e Controle de Investimentos
A2: Corretora: Rico
A3: 💡 DICA B3: Para cotação em tempo real no Excel, selecione os Tickers com 'BVMF:' e converta em Dados > Ações.
A5: Ticker B3 | B5: Ativo | C5: Preço Atual (Cotação) | D5: Último Rendimento | E5: Cota Mágica (Qtd p/ Reinvestir) | F5: DY 12m | G5: P/VP | H5: Segmento
A6: BVMF:KNCR11 | B6: Kinea Rendimentos Imobiliários | C6: 10.8 | D6: 0.12 | E6: =IFERROR(ROUNDUP(C6/D6, 0), 0) | F6: 0.135 | G6: 1.04 | H6: Títulos e Valores Mobiliários
A7: BVMF:ISNT11 | B7: Itaú Isento Março 28 | C7: 98.5 | D7: 1 | E7: =IFERROR(ROUNDUP(C7/D7, 0), 0) | F7: 0.12 | G7: 1.01 | H7: FI-Infra
A8: BVMF:HGLG11 | B8: Pátria Log | C8: 165.5 | D8: 1.1 | E8: =IFERROR(ROUNDUP(C8/D8, 0), 0) | F8: 0.0913 | G8: 0.87 | H8: Logístico / Galpões
A9: BVMF:KNIP11 | B9: Kinea Índice de Preços | C9: 95 | D9: 0.9 | E9: =IFERROR(ROUNDUP(C9/D9, 0), 0) | F9: 0.1139 | G9: 0.96 | H9: Títulos e Valores Mobiliários
A10: BVMF:BTLG11 | B10: Btg Pactual Logística | C10: 102 | D10: 0.84 | E10: =IFERROR(ROUNDUP(C10/D10, 0), 0) | F10: 0.0983 | G10: 0.91 | H10: Logístico / Galpões
A11: BVMF:XPML11 | B11: XP Malls | C11: 112 | D11: 0.92 | E11: =IFERROR(ROUNDUP(C11/D11, 0), 0) | F11: 0.1002 | G11: 0.92 | H11: Shoppings / Varejo
A12: BVMF:ISEN11 | B12: Itaú Isento Março 29 | C12: 94 | D12: 0.95 | E12: =IFERROR(ROUNDUP(C12/D12, 0), 0) | F12: 0.115 | G12: 1.02 | H12: FI-Infra
A13: BVMF:TRXF11 | B13: TRX Real Estate | C13: 108 | D13: 1.3 | E13: =IFERROR(ROUNDUP(C13/D13, 0), 0) | F13: 0.1505 | G13: 0.82 | H13: Híbrido
A14: BVMF:MXRF11 | B14: Maxi Renda | C14: 10.25 | D14: 0.09 | E14: =IFERROR(ROUNDUP(C14/D14, 0), 0) | F14: 0.129 | G14: 1 | H14: Híbrido
A15: BVMF:KNRI11 | B15: Kinea Renda Imobiliária | C15: 155 | D15: 1 | E15: =IFERROR(ROUNDUP(C15/D15, 0), 0) | F15: 0.0857 | G15: 0.93 | H15: Híbrido

Sheet CARTEIRA
A1: 📊 Simulador e Controle de Investimentos
A2: Corretora: Rico
A3: 📌 REGRA PM: Custo Total = (Qtd * Preço) + Taxas. O PM é ajustado nas compras e mantido nas vendas.
A5: Data | B5: Corretora | C5: Ticker | D5: Tipo | E5: Qtd | F5: Preço Compras | G5: Taxas (R$) | H5: Custo Total Compra | I5: Preço Médio (PM) | J5: Preço Atual | K5: Valor Atual | L5: Resultado | M5: Rentabilidade | N5: Segmento
A6: 2026-08-10 | B6: Rico | C6: BVMF:KNCR11 | D6: FII | E6: 100 | F6: 10.5 | G6: 1.5 | H6: =(E6*F6)+G6 | I6: =IFERROR(H6/E6, 0) | J6: =IFERROR(VLOOKUP(C6, BASE_ATIVOS!$A$6:$H$100, 3, FALSE), 0) | K6: =E6*J6 | L6: =K6-H6 | M6: =IFERROR(L6/H6, 0) | N6: =IFERROR(VLOOKUP(C6, BASE_ATIVOS!$A$6:$H$100, 8, FALSE), "Outros")
A7: 2026-08-12 | B7: Rico | C7: BVMF:HGLG11 | D7: FII | E7: 50 | F7: 160 | G7: 3.2 | H7: =(E7*F7)+G7 | I7: =IFERROR(H7/E7, 0) | J7: =IFERROR(VLOOKUP(C7, BASE_ATIVOS!$A$6:$H$100, 3, FALSE), 0) | K7: =E7*J7 | L7: =K7-H7 | M7: =IFERROR(L7/H7, 0) | N7: =IFERROR(VLOOKUP(C7, BASE_ATIVOS!$A$6:$H$100, 8, FALSE), "Outros")
A8: 2026-08-15 | B8: Rico | C8: BVMF:MXRF11 | D8: FII | E8: 500 | F8: 10.1 | G8: 2 | H8: =(E8*F8)+G8 | I8: =IFERROR(H8/E8, 0) | J8: =IFERROR(VLOOKUP(C8, BASE_ATIVOS!$A$6:$H$100, 3, FALSE), 0) | K8: =E8*J8 | L8: =K8-H8 | M8: =IFERROR(L8/H8, 0) | N8: =IFERROR(VLOOKUP(C8, BASE_ATIVOS!$A$6:$H$100, 8, FALSE), "Outros")
A9: 2026-08-18 | B9: Rico | C9: BVMF:ISNT11 | D9: FI-Infra | E9: 200 | F9: 100 | G9: 4 | H9: =(E9*F9)+G9 | I9: =IFERROR(H9/E9, 0) | J9: =IFERROR(VLOOKUP(C9, BASE_ATIVOS!$A$6:$H$100, 3, FALSE), 0) | K9: =E9*J9 | L9: =K9-H9 | M9: =IFERROR(L9/H9, 0) | N9: =IFERROR(VLOOKUP(C9, BASE_ATIVOS!$A$6:$H$100, 8, FALSE), "Outros")
H10: =IF(E10<>"", (E10*F10)+G10, 0) | I10: =IFERROR(H10/E10, 0) | J10: =IF(C10<>"", IFERROR(VLOOKUP(C10, BASE_ATIVOS!$A$6:$H$100, 3, FALSE), 0), 0) | K10: =IF(E10<>"", E10*J10, 0) | L10: =IF(E10<>"", K10-H10, 0) | M10: =IFERROR(IF(H10>0, L10/H10, 0), 0) | N10: =IF(C10<>"", IFERROR(VLOOKUP(C10, BASE_ATIVOS!$A$6:$H$100, 8, FALSE), "Outros"), "")
H11: =IF(E11<>"", (E11*F11)+G11, 0) | I11: =IFERROR(H11/E11, 0) | J11: =IF(C11<>"", IFERROR(VLOOKUP(C11, BASE_ATIVOS!$A$6:$H$100, 3, FALSE), 0), 0) | K11: =IF(E11<>"", E11*J11, 0) | L11: =IF(E11<>"", K11-H11, 0) | M11: =IFERROR(IF(H11>0, L11/H11, 0), 0) | N11: =IF(C11<>"", IFERROR(VLOOKUP(C11, BASE_ATIVOS!$A$6:$H$100, 8, FALSE), "Outros"), "")
H12: =IF(E12<>"", (E12*F12)+G12, 0) | I12: =IFERROR(H12/E12, 0) | J12: =IF(C12<>"", IFERROR(VLOOKUP(C12, BASE_ATIVOS!$A$6:$H$100, 3, FALSE), 0), 0) | K12: =IF(E12<>"", E12*J12, 0) | L12: =IF(E12<>"", K12-H12, 0) | M12: =IFERROR(IF(H12>0, L12/H12, 0), 0) | N12: =IF(C12<>"", IFERROR(VLOOKUP(C12, BASE_ATIVOS!$A$6:$H$100, 8, FALSE), "Outros"), "")
H13: =IF(E13<>"", (E13*F13)+G13, 0) | I13: =IFERROR(H13/E13, 0) | J13: =IF(C13<>"", IFERROR(VLOOKUP(C13, BASE_ATIVOS!$A$6:$H$100, 3, FALSE), 0), 0) | K13: =IF(E13<>"", E13*J13, 0) | L13: =IF(E13<>"", K13-H13, 0) | M13: =IFERROR(IF(H13>0, L13/H13, 0), 0) | N13: =IF(C13<>"", IFERROR(VLOOKUP(C13, BASE_ATIVOS!$A$6:$H$100, 8, FALSE), "Outros"), "")
H14: =IF(E14<>"", (E14*F14)+G14, 0) | I14: =IFERROR(H14/E14, 0) | J14: =IF(C14<>"", IFERROR(VLOOKUP(C14, BASE_ATIVOS!$A$6:$H$100, 3, FALSE), 0), 0) | K14: =IF(E14<>"", E14*J14, 0) | L14: =IF(E14<>"", K14-H14, 0) | M14: =IFERROR(IF(H14>0, L14/H14, 0), 0) | N14: =IF(C14<>"", IFERROR(VLOOKUP(C14, BASE_ATIVOS!$A$6:$H$100, 8, FALSE), "Outros"), "")
H15: =IF(E15<>"", (E15*F15)+G15, 0) | I15: =IFERROR(H15/E15, 0) | J15: =IF(C15<>"", IFERROR(VLOOKUP(C15, BASE_ATIVOS!$A$6:$H$100, 3, FALSE), 0), 0) | K15: =IF(E15<>"", E15*J15, 0) | L15: =IF(E15<>"", K15-H15, 0) | M15: =IFERROR(IF(H15>0, L15/H15, 0), 0) | N15: =IF(C15<>"", IFERROR(VLOOKUP(C15, BASE_ATIVOS!$A$6:$H$100, 8, FALSE), "Outros"), "")
H16: =IF(E16<>"", (E16*F16)+G16, 0) | I16: =IFERROR(H16/E16, 0) | J16: =IF(C16<>"", IFERROR(VLOOKUP(C16, BASE_ATIVOS!$A$6:$H$100, 3, FALSE), 0), 0) | K16: =IF(E16<>"", E16*J16, 0) | L16: =IF(E16<>"", K16-H16, 0) | M16: =IFERROR(IF(H16>0, L16/H16, 0), 0) | N16: =IF(C16<>"", IFERROR(VLOOKUP(C16, BASE_ATIVOS!$A$6:$H$100, 8, FALSE), "Outros"), "")
H17: =IF(E17<>"", (E17*F17)+G17, 0) | I17: =IFERROR(H17/E17, 0) | J17: =IF(C17<>"", IFERROR(VLOOKUP(C17, BASE_ATIVOS!$A$6:$H$100, 3, FALSE), 0), 0) | K17: =IF(E17<>"", E17*J17, 0) | L17: =IF(E17<>"", K17-H17, 0) | M17: =IFERROR(IF(H17>0, L17/H17, 0), 0) | N17: =IF(C17<>"", IFERROR(VLOOKUP(C17, BASE_ATIVOS!$A$6:$H$100, 8, FALSE), "Outros"), "")
H18: =IF(E18<>"", (E18*F18)+G18, 0) | I18: =IFERROR(H18/E18, 0) | J18: =IF(C18<>"", IFERROR(VLOOKUP(C18, BASE_ATIVOS!$A$6:$H$100, 3, FALSE), 0), 0) | K18: =IF(E18<>"", E18*J18, 0) | L18: =IF(E18<>"", K18-H18, 0) | M18: =IFERROR(IF(H18>0, L18/H18, 0), 0) | N18: =IF(C18<>"", IFERROR(VLOOKUP(C18, BASE_ATIVOS!$A$6:$H$100, 8, FALSE), "Outros"), "")
H19: =IF(E19<>"", (E19*F19)+G19, 0) | I19: =IFERROR(H19/E19, 0) | J19: =IF(C19<>"", IFERROR(VLOOKUP(C19, BASE_ATIVOS!$A$6:$H$100, 3, FALSE), 0), 0) | K19: =IF(E19<>"", E19*J19, 0) | L19: =IF(E19<>"", K19-H19, 0) | M19: =IFERROR(IF(H19>0, L19/H19, 0), 0) | N19: =IF(C19<>"", IFERROR(VLOOKUP(C19, BASE_ATIVOS!$A$6:$H$100, 8, FALSE), "Outros"), "")
H20: =IF(E20<>"", (E20*F20)+G20, 0) | I20: =IFERROR(H20/E20, 0) | J20: =IF(C20<>"", IFERROR(VLOOKUP(C20, BASE_ATIVOS!$A$6:$H$100, 3, FALSE), 0), 0) | K20: =IF(E20<>"", E20*J20, 0) | L20: =IF(E20<>"", K20-H20, 0) | M20: =IFERROR(IF(H20>0, L20/H20, 0), 0) | N20: =IF(C20<>"", IFERROR(VLOOKUP(C20, BASE_ATIVOS!$A$6:$H$100, 8, FALSE), "Outros"), "")
H21: =IF(E21<>"", (E21*F21)+G21, 0) | I21: =IFERROR(H21/E21, 0) | J21: =IF(C21<>"", IFERROR(VLOOKUP(C21, BASE_ATIVOS!$A$6:$H$100, 3, FALSE), 0), 0) | K21: =IF(E21<>"", E21*J21, 0) | L21: =IF(E21<>"", K21-H21, 0) | M21: =IFERROR(IF(H21>0, L21/H21, 0), 0) | N21: =IF(C21<>"", IFERROR(VLOOKUP(C21, BASE_ATIVOS!$A$6:$H$100, 8, FALSE), "Outros"), "")
... H29: =IF(E29<>"", (E29*F29)+G29, 0) | I29: =IFERROR(H29/E29, 0) | J29: =IF(C29<>"", IFERROR(VLOOKUP(C29, BASE_ATIVOS!$A$6:$H$100, 3, FALSE), 0), 0) | K29: =IF(E29<>"", E29*J29, 0) | L29: =IF(E29<>"", K29-H29, 0) | M29: =IFERROR(IF(H29>0, L29/H29, 0), 0) | N29: =IF(C29<>"", IFERROR(VLOOKUP(C29, BASE_ATIVOS!$A$6:$H$100, 8, FALSE), "Outros"), "")

Sheet PROVENTOS
A1: 📊 Simulador e Controle de Investimentos
A2: Corretora: Rico
A4: Data | B4: Mês | C4: Corretora | D4: Ticker | E4: Qtd Cotas | F4: Rendimento por Cota | G4: Renda Total Recebida
A5: 2026-08-15 | B5: Agosto | C5: Rico | D5: BVMF:KNCR11 | E5: 100 | F5: 0.12 | G5: =E5*F5
A6: 2026-08-15 | B6: Agosto | C6: Rico | D6: BVMF:HGLG11 | E6: 50 | F6: 1.1 | G6: =E6*F6
A7: 2026-08-15 | B7: Agosto | C7: Rico | D7: BVMF:MXRF11 | E7: 500 | F7: 0.09 | G7: =E7*F7
G8: =IF(E8<>"", E8*F8, 0)
G9: =IF(E9<>"", E9*F9, 0)
G10: =IF(E10<>"", E10*F10, 0)
G11: =IF(E11<>"", E11*F11, 0)
G12: =IF(E12<>"", E12*F12, 0)
G13: =IF(E13<>"", E13*F13, 0)
G14: =IF(E14<>"", E14*F14, 0)
G15: =IF(E15<>"", E15*F15, 0)
G16: =IF(E16<>"", E16*F16, 0)
G17: =IF(E17<>"", E17*F17, 0)
G18: =IF(E18<>"", E18*F18, 0)
G19: =IF(E19<>"", E19*F19, 0)
... G29: =IF(E29<>"", E29*F29, 0)

Sheet APORTES
A1: 📊 Simulador e Controle de Investimentos
A2: Corretora: Rico
A4: Data | B4: Mês | C4: Corretora | D4: Valor (R$) | E4: Obs / Origem
A5: 2026-08-05 | B5: Agosto | C5: Rico | D5: 500 | E5: Aporte mensal regular
A6: 2026-09-05 | B6: Setembro | C6: Rico | D6: 500 | E6: Aporte mensal regular
A7: 2026-10-05 | B7: Outubro | C7: Rico | D7: 600 | E7: Aporte + sobra de orçamento

Sheet SIMULADOR
A1: 📊 Simulador e Controle de Investimentos
A2: Corretora: Rico
A3: 💡 NOTA DEV: Altere os valores nas células amarelas. O simulador considera o efeito Bola de Neve (reinvestimento automático de dividendos).
A5: Parâmetro | B5: Valor
A6: Aporte Inicial | B6: 5000
A7: Aporte Mensal | B7: 500
A8: Rentabilidade Mensal (Valorização) | B8: 0.008
A9: Dividend Yield Mensal (Renda) | B9: 0.008
A10: Período de Projeção (Meses) | B10: 60
A12: Linha do Tempo - Projeção de Renda e Reinvestimento
A13: Mês | B13: Aporte do Mês | C13: Total do Bolso | D13: Patrimônio Acumulado | E13: Dividendos Recebidos (Bola de Neve) | F13: Valorização Capital
A14: 1 | B14: =$B$7 | C14: =$B$6+B14 | D14: =($B$6+B14)*(1+$B$8+$B$9) | E14: =($B$6+B14)*$B$9 | F14: =($B$6+B14)*$B$8
A15: 2 | B15: =$B$7 | C15: =C14+B15 | D15: =(D14+B15)*(1+$B$8+$B$9) | E15: =(D14+B15)*$B$9 | F15: =(D14+B15)*$B$8
A16: 3 | B16: =$B$7 | C16: =C15+B16 | D16: =(D15+B16)*(1+$B$8+$B$9) | E16: =(D15+B16)*$B$9 | F16: =(D15+B16)*$B$8
A17: 4 | B17: =$B$7 | C17: =C16+B17 | D17: =(D16+B17)*(1+$B$8+$B$9) | E17: =(D16+B17)*$B$9 | F17: =(D16+B17)*$B$8
A18: 5 | B18: =$B$7 | C18: =C17+B18 | D18: =(D17+B18)*(1+$B$8+$B$9) | E18: =(D17+B18)*$B$9 | F18: =(D17+B18)*$B$8
A19: 6 | B19: =$B$7 | C19: =C18+B19 | D19: =(D18+B19)*(1+$B$8+$B$9) | E19: =(D18+B19)*$B$9 | F19: =(D18+B19)*$B$8
A20: 7 | B20: =$B$7 | C20: =C19+B20 | D20: =(D19+B20)*(1+$B$8+$B$9) | E20: =(D19+B20)*$B$9 | F20: =(D19+B20)*$B$8
A21: 8 | B21: =$B$7 | C21: =C20+B21 | D21: =(D20+B21)*(1+$B$8+$B$9) | E21: =(D20+B21)*$B$9 | F21: =(D20+B21)*$B$8
A22: 9 | B22: =$B$7 | C22: =C21+B22 | D22: =(D21+B22)*(1+$B$8+$B$9) | E22: =(D21+B22)*$B$9 | F22: =(D21+B22)*$B$8
A23: 10 | B23: =$B$7 | C23: =C22+B23 | D23: =(D22+B23)*(1+$B$8+$B$9) | E23: =(D22+B23)*$B$9 | F23: =(D22+B23)*$B$8
A24: 11 | B24: =$B$7 | C24: =C23+B24 | D24: =(D23+B24)*(1+$B$8+$B$9) | E24: =(D23+B24)*$B$9 | F24: =(D23+B24)*$B$8
A25: 12 | B25: =$B$7 | C25: =C24+B25 | D25: =(D24+B25)*(1+$B$8+$B$9) | E25: =(D24+B25)*$B$9 | F25: =(D24+B25)*$B$8
A26: 13 | B26: =$B$7 | C26: =C25+B26 | D26: =(D25+B26)*(1+$B$8+$B$9) | E26: =(D25+B26)*$B$9 | F26: =(D25+B26)*$B$8
... A73: 60 | B73: =$B$7 | C73: =C72+B73 | D73: =(D72+B73)*(1+$B$8+$B$9) | E73: =(D72+B73)*$B$9 | F73: =(D72+B73)*$B$8
